{
 "cells": [
  {
   "cell_type": "markdown",
   "metadata": {},
   "source": [
    "## try"
   ]
  },
  {
   "cell_type": "code",
   "execution_count": 1,
   "metadata": {},
   "outputs": [
    {
     "name": "stdout",
     "output_type": "stream",
     "text": [
      "try...\n",
      "except: division by zero\n",
      "finally...\n",
      "END\n"
     ]
    }
   ],
   "source": [
    "try:\n",
    "    print('try...')\n",
    "    r = 10 / 0\n",
    "    print('result:', r)\n",
    "except ZeroDivisionError as e:\n",
    "    print('except:', e)\n",
    "finally:\n",
    "    print('finally...')\n",
    "print('END')"
   ]
  },
  {
   "cell_type": "markdown",
   "metadata": {},
   "source": [
    "如果可能存在多种错误，可以使用多个except，另外可以在except语句块后面加一个else，当没有错误发生时，自动执行else语句。\n"
   ]
  },
  {
   "cell_type": "code",
   "execution_count": 2,
   "metadata": {},
   "outputs": [
    {
     "name": "stdout",
     "output_type": "stream",
     "text": [
      "try...\n",
      "result: 5.0\n",
      "no error!\n",
      "finally...\n",
      "END\n"
     ]
    }
   ],
   "source": [
    "try:\n",
    "    print('try...')\n",
    "    r = 10 / int('2')\n",
    "    print('result:', r)\n",
    "except ValueError as e:\n",
    "    print('ValueError:', e)\n",
    "except ZeroDivisionError as e:\n",
    "    print('ZeroDivisionError:', e)\n",
    "else:\n",
    "    print('no error!')\n",
    "finally:\n",
    "    print('finally...')\n",
    "print('END')"
   ]
  },
  {
   "cell_type": "markdown",
   "metadata": {},
   "source": [
    "Python的错误其实也是class，所有的错误类型都继承自BaseException，所以在使用except时需要注意的是，它不但捕获该类型的错误，还把其子类也“一网打尽”。比如："
   ]
  },
  {
   "cell_type": "code",
   "execution_count": 4,
   "metadata": {},
   "outputs": [],
   "source": [
    "# 无法获取UnicodeError错误，因为UnicodeError是ValueError的子类。\n",
    "try:\n",
    "   pass\n",
    "except ValueError as e:\n",
    "    print('ValueError')\n",
    "except UnicodeError as e:\n",
    "    print('UnicodeError')"
   ]
  },
  {
   "cell_type": "markdown",
   "metadata": {},
   "source": [
    "## err.py\n",
    "如果错误没有被捕获，它就会一直往上抛，最后被Python解释器捕获，打印一个错误信息，然后程序退出。来看看err.py：\n"
   ]
  },
  {
   "cell_type": "code",
   "execution_count": 5,
   "metadata": {},
   "outputs": [
    {
     "ename": "ZeroDivisionError",
     "evalue": "division by zero",
     "output_type": "error",
     "traceback": [
      "\u001b[1;31m---------------------------------------------------------------------------\u001b[0m",
      "\u001b[1;31mZeroDivisionError\u001b[0m                         Traceback (most recent call last)",
      "\u001b[1;32m<ipython-input-5-43ad0f8735f4>\u001b[0m in \u001b[0;36m<module>\u001b[1;34m()\u001b[0m\n\u001b[0;32m      9\u001b[0m     \u001b[0mbar\u001b[0m\u001b[1;33m(\u001b[0m\u001b[1;34m'0'\u001b[0m\u001b[1;33m)\u001b[0m\u001b[1;33m\u001b[0m\u001b[0m\n\u001b[0;32m     10\u001b[0m \u001b[1;33m\u001b[0m\u001b[0m\n\u001b[1;32m---> 11\u001b[1;33m \u001b[0mmain\u001b[0m\u001b[1;33m(\u001b[0m\u001b[1;33m)\u001b[0m\u001b[1;33m\u001b[0m\u001b[0m\n\u001b[0m",
      "\u001b[1;32m<ipython-input-5-43ad0f8735f4>\u001b[0m in \u001b[0;36mmain\u001b[1;34m()\u001b[0m\n\u001b[0;32m      7\u001b[0m \u001b[1;33m\u001b[0m\u001b[0m\n\u001b[0;32m      8\u001b[0m \u001b[1;32mdef\u001b[0m \u001b[0mmain\u001b[0m\u001b[1;33m(\u001b[0m\u001b[1;33m)\u001b[0m\u001b[1;33m:\u001b[0m\u001b[1;33m\u001b[0m\u001b[0m\n\u001b[1;32m----> 9\u001b[1;33m     \u001b[0mbar\u001b[0m\u001b[1;33m(\u001b[0m\u001b[1;34m'0'\u001b[0m\u001b[1;33m)\u001b[0m\u001b[1;33m\u001b[0m\u001b[0m\n\u001b[0m\u001b[0;32m     10\u001b[0m \u001b[1;33m\u001b[0m\u001b[0m\n\u001b[0;32m     11\u001b[0m \u001b[0mmain\u001b[0m\u001b[1;33m(\u001b[0m\u001b[1;33m)\u001b[0m\u001b[1;33m\u001b[0m\u001b[0m\n",
      "\u001b[1;32m<ipython-input-5-43ad0f8735f4>\u001b[0m in \u001b[0;36mbar\u001b[1;34m(s)\u001b[0m\n\u001b[0;32m      4\u001b[0m \u001b[1;33m\u001b[0m\u001b[0m\n\u001b[0;32m      5\u001b[0m \u001b[1;32mdef\u001b[0m \u001b[0mbar\u001b[0m\u001b[1;33m(\u001b[0m\u001b[0ms\u001b[0m\u001b[1;33m)\u001b[0m\u001b[1;33m:\u001b[0m\u001b[1;33m\u001b[0m\u001b[0m\n\u001b[1;32m----> 6\u001b[1;33m     \u001b[1;32mreturn\u001b[0m \u001b[0mfoo\u001b[0m\u001b[1;33m(\u001b[0m\u001b[0ms\u001b[0m\u001b[1;33m)\u001b[0m \u001b[1;33m*\u001b[0m \u001b[1;36m2\u001b[0m\u001b[1;33m\u001b[0m\u001b[0m\n\u001b[0m\u001b[0;32m      7\u001b[0m \u001b[1;33m\u001b[0m\u001b[0m\n\u001b[0;32m      8\u001b[0m \u001b[1;32mdef\u001b[0m \u001b[0mmain\u001b[0m\u001b[1;33m(\u001b[0m\u001b[1;33m)\u001b[0m\u001b[1;33m:\u001b[0m\u001b[1;33m\u001b[0m\u001b[0m\n",
      "\u001b[1;32m<ipython-input-5-43ad0f8735f4>\u001b[0m in \u001b[0;36mfoo\u001b[1;34m(s)\u001b[0m\n\u001b[0;32m      1\u001b[0m \u001b[1;31m# err.py:\u001b[0m\u001b[1;33m\u001b[0m\u001b[1;33m\u001b[0m\u001b[0m\n\u001b[0;32m      2\u001b[0m \u001b[1;32mdef\u001b[0m \u001b[0mfoo\u001b[0m\u001b[1;33m(\u001b[0m\u001b[0ms\u001b[0m\u001b[1;33m)\u001b[0m\u001b[1;33m:\u001b[0m\u001b[1;33m\u001b[0m\u001b[0m\n\u001b[1;32m----> 3\u001b[1;33m     \u001b[1;32mreturn\u001b[0m \u001b[1;36m10\u001b[0m \u001b[1;33m/\u001b[0m \u001b[0mint\u001b[0m\u001b[1;33m(\u001b[0m\u001b[0ms\u001b[0m\u001b[1;33m)\u001b[0m\u001b[1;33m\u001b[0m\u001b[0m\n\u001b[0m\u001b[0;32m      4\u001b[0m \u001b[1;33m\u001b[0m\u001b[0m\n\u001b[0;32m      5\u001b[0m \u001b[1;32mdef\u001b[0m \u001b[0mbar\u001b[0m\u001b[1;33m(\u001b[0m\u001b[0ms\u001b[0m\u001b[1;33m)\u001b[0m\u001b[1;33m:\u001b[0m\u001b[1;33m\u001b[0m\u001b[0m\n",
      "\u001b[1;31mZeroDivisionError\u001b[0m: division by zero"
     ]
    }
   ],
   "source": [
    "# err.py:\n",
    "def foo(s):\n",
    "    return 10 / int(s)\n",
    "\n",
    "def bar(s):\n",
    "    return foo(s) * 2\n",
    "\n",
    "def main():\n",
    "    bar('0')\n",
    "\n",
    "main()"
   ]
  },
  {
   "cell_type": "markdown",
   "metadata": {},
   "source": [
    "## logging"
   ]
  },
  {
   "cell_type": "markdown",
   "metadata": {},
   "source": [
    "如果不捕获错误，自然可以让Python解释器来打印出错误堆栈，但程序也被结束了。既然我们能捕获错误，就可以把错误堆栈打印出来，然后分析错误原因，同时，让程序继续执行下去。\n",
    "Python内置的logging模块可以非常容易地记录错误信息："
   ]
  },
  {
   "cell_type": "code",
   "execution_count": 46,
   "metadata": {},
   "outputs": [
    {
     "name": "stderr",
     "output_type": "stream",
     "text": [
      "WARNING:root:warning message\n",
      "ERROR:root:error message\n",
      "CRITICAL:root:critical message\n"
     ]
    }
   ],
   "source": [
    "import logging\n",
    "logging.debug('debug message')\n",
    "logging.info('info message')\n",
    "logging.warning('warning message')\n",
    "logging.error('error message')\n",
    "logging.critical('critical message')"
   ]
  },
  {
   "cell_type": "code",
   "execution_count": 47,
   "metadata": {},
   "outputs": [
    {
     "name": "stderr",
     "output_type": "stream",
     "text": [
      "ERROR:root:division by zero\n",
      "Traceback (most recent call last):\n",
      "  File \"<ipython-input-47-50dd10eca926>\", line 13, in main\n",
      "    bar('0')\n",
      "  File \"<ipython-input-47-50dd10eca926>\", line 9, in bar\n",
      "    return foo(s) * 2\n",
      "  File \"<ipython-input-47-50dd10eca926>\", line 6, in foo\n",
      "    return 10 / int(s)\n",
      "ZeroDivisionError: division by zero\n"
     ]
    },
    {
     "name": "stdout",
     "output_type": "stream",
     "text": [
      "END\n"
     ]
    }
   ],
   "source": [
    "# err_logging.py\n",
    "\n",
    "import logging\n",
    "\n",
    "def foo(s):\n",
    "    return 10 / int(s)\n",
    "\n",
    "def bar(s):\n",
    "    return foo(s) * 2\n",
    "\n",
    "def main():\n",
    "    try:\n",
    "        bar('0')\n",
    "    except Exception as e:\n",
    "        logging.exception(e)\n",
    "\n",
    "main()\n",
    "print('END')"
   ]
  },
  {
   "cell_type": "markdown",
   "metadata": {},
   "source": [
    "## raise"
   ]
  },
  {
   "cell_type": "markdown",
   "metadata": {},
   "source": [
    "因为错误是class，捕获一个错误就是捕获到该class的一个实例。因此，错误并不是凭空产生的，而是有意创建并抛出的。Python的内置函数会抛出很多类型的错误，我们自己编写的函数也可以抛出错误。\n",
    "如果要抛出错误，首先根据需要，可以定义一个错误的class，选择好继承关系，然后，用raise语句抛出一个错误的实例："
   ]
  },
  {
   "cell_type": "code",
   "execution_count": 48,
   "metadata": {
    "scrolled": false
   },
   "outputs": [
    {
     "name": "stdout",
     "output_type": "stream",
     "text": [
      "ValueError!\n"
     ]
    },
    {
     "ename": "ValueError",
     "evalue": "invalid value: 0",
     "output_type": "error",
     "traceback": [
      "\u001b[1;31m---------------------------------------------------------------------------\u001b[0m",
      "\u001b[1;31mValueError\u001b[0m                                Traceback (most recent call last)",
      "\u001b[1;32m<ipython-input-48-739e80ef9b01>\u001b[0m in \u001b[0;36m<module>\u001b[1;34m()\u001b[0m\n\u001b[0;32m     14\u001b[0m         \u001b[1;32mraise\u001b[0m\u001b[1;33m\u001b[0m\u001b[0m\n\u001b[0;32m     15\u001b[0m \u001b[1;33m\u001b[0m\u001b[0m\n\u001b[1;32m---> 16\u001b[1;33m \u001b[0mbar\u001b[0m\u001b[1;33m(\u001b[0m\u001b[1;33m)\u001b[0m\u001b[1;33m\u001b[0m\u001b[0m\n\u001b[0m",
      "\u001b[1;32m<ipython-input-48-739e80ef9b01>\u001b[0m in \u001b[0;36mbar\u001b[1;34m()\u001b[0m\n\u001b[0;32m      9\u001b[0m \u001b[1;32mdef\u001b[0m \u001b[0mbar\u001b[0m\u001b[1;33m(\u001b[0m\u001b[1;33m)\u001b[0m\u001b[1;33m:\u001b[0m\u001b[1;33m\u001b[0m\u001b[0m\n\u001b[0;32m     10\u001b[0m     \u001b[1;32mtry\u001b[0m\u001b[1;33m:\u001b[0m\u001b[1;33m\u001b[0m\u001b[0m\n\u001b[1;32m---> 11\u001b[1;33m         \u001b[0mfoo\u001b[0m\u001b[1;33m(\u001b[0m\u001b[1;34m'0'\u001b[0m\u001b[1;33m)\u001b[0m\u001b[1;33m\u001b[0m\u001b[0m\n\u001b[0m\u001b[0;32m     12\u001b[0m     \u001b[1;32mexcept\u001b[0m \u001b[0mValueError\u001b[0m \u001b[1;32mas\u001b[0m \u001b[0me\u001b[0m\u001b[1;33m:\u001b[0m\u001b[1;33m\u001b[0m\u001b[0m\n\u001b[0;32m     13\u001b[0m         \u001b[0mprint\u001b[0m\u001b[1;33m(\u001b[0m\u001b[1;34m'ValueError!'\u001b[0m\u001b[1;33m)\u001b[0m\u001b[1;33m\u001b[0m\u001b[0m\n",
      "\u001b[1;32m<ipython-input-48-739e80ef9b01>\u001b[0m in \u001b[0;36mfoo\u001b[1;34m(s)\u001b[0m\n\u001b[0;32m      4\u001b[0m     \u001b[0mn\u001b[0m \u001b[1;33m=\u001b[0m \u001b[0mint\u001b[0m\u001b[1;33m(\u001b[0m\u001b[0ms\u001b[0m\u001b[1;33m)\u001b[0m\u001b[1;33m\u001b[0m\u001b[0m\n\u001b[0;32m      5\u001b[0m     \u001b[1;32mif\u001b[0m \u001b[0mn\u001b[0m\u001b[1;33m==\u001b[0m\u001b[1;36m0\u001b[0m\u001b[1;33m:\u001b[0m\u001b[1;33m\u001b[0m\u001b[0m\n\u001b[1;32m----> 6\u001b[1;33m         \u001b[1;32mraise\u001b[0m \u001b[0mValueError\u001b[0m\u001b[1;33m(\u001b[0m\u001b[1;34m'invalid value: %s'\u001b[0m \u001b[1;33m%\u001b[0m \u001b[0ms\u001b[0m\u001b[1;33m)\u001b[0m\u001b[1;33m\u001b[0m\u001b[0m\n\u001b[0m\u001b[0;32m      7\u001b[0m     \u001b[1;32mreturn\u001b[0m \u001b[1;36m10\u001b[0m \u001b[1;33m/\u001b[0m \u001b[0mn\u001b[0m\u001b[1;33m\u001b[0m\u001b[0m\n\u001b[0;32m      8\u001b[0m \u001b[1;33m\u001b[0m\u001b[0m\n",
      "\u001b[1;31mValueError\u001b[0m: invalid value: 0"
     ]
    }
   ],
   "source": [
    "# err_reraise.py\n",
    "\n",
    "def foo(s):\n",
    "    n = int(s)\n",
    "    if n==0:\n",
    "        raise ValueError('invalid value: %s' % s)\n",
    "    return 10 / n\n",
    "\n",
    "def bar():\n",
    "    try:\n",
    "        foo('0')\n",
    "    except ValueError as e:\n",
    "        print('ValueError!')\n",
    "        raise\n",
    "\n",
    "bar()"
   ]
  },
  {
   "cell_type": "markdown",
   "metadata": {},
   "source": [
    "在bar()函数中，我们明明已经捕获了错误，但是，打印一个ValueError!后，又把错误通过raise语句抛出去了，这不有病么？<br>\n",
    "其实这种错误处理方式不但没病，而且相当常见。捕获错误目的只是记录一下，便于后续追踪。但是，由于当前函数不知道应该怎么处理该错误，所以，最恰当的方式是继续往上抛，让顶层调用者去处理。好比一个员工处理不了一个问题时，就把问题抛给他的老板，如果他的老板也处理不了，就一直往上抛，最终会抛给CEO去处理。"
   ]
  },
  {
   "cell_type": "code",
   "execution_count": null,
   "metadata": {},
   "outputs": [],
   "source": []
  }
 ],
 "metadata": {
  "kernelspec": {
   "display_name": "Python 3",
   "language": "python",
   "name": "python3"
  },
  "language_info": {
   "codemirror_mode": {
    "name": "ipython",
    "version": 3
   },
   "file_extension": ".py",
   "mimetype": "text/x-python",
   "name": "python",
   "nbconvert_exporter": "python",
   "pygments_lexer": "ipython3",
   "version": "3.6.0"
  }
 },
 "nbformat": 4,
 "nbformat_minor": 2
}
